<?xml version="1.0" encoding="utf-8"?>
<robot xmlns:xacro="http://www.ros.org/wiki/xacro" name="robot">
  <!-- 
  This URDF was automatically created by SolidWorks to URDF Exporter! Originally created by Stephen
  Brawner (brawner@gmail.com) 
     Commit Version: 1.6.0-4-g7f85cfe  Build Version: 1.6.7995.38578
     For more information, please see http://wiki.ros.org/sw_urdf_exporter 
  -->

  <xacro:include filename="$(find addverb_cobot_description)/urdf/cobot_gazebo.xacro"/>
  <!--<xacro:include filename="$(find addverb_cobot_description)/ros2_control/heal.ros2_control.xacro"/>-->
  <xacro:include filename="$(find addverb_cobot_description)/ros2_control/newcontrol.xacro"/>
  <!--<xacro:include filename="$(find syncro_gripper_moveit_config)/config/robot.ros2_control.xacro"/>-->

  <link name="world"/>

  <link name="base_link">
    <inertial>
      <mass value="1.0"/>
      <origin xyz = "0 0 0" rpy = "0 0 0" />
      <inertia ixx="0.01" ixy="0.0" ixz="0.0"
                iyy="0.01" iyz="0.0"
                izz="0.01"/>
    </inertial>
    <visual>
      <origin xyz="0 0 0" rpy="0 0 0" />
      <geometry>
        <mesh filename="package://addverb_cobot_description/meshes/base_link.STL" />
      </geometry>
      <material name="">
        <color rgba="0.75294 0.75294 0.75294 1" />
      </material>
    </visual>
    <collision>
      <origin xyz="0 0 0" rpy="0 0 0" />
      <geometry>
        <mesh filename="package://addverb_cobot_description/meshes/base_link.STL" />
      </geometry>
    </collision>
  </link>

  <joint name="virtual_joint" type = 'fixed'>
    <parent link='world' />
    <child link='base_link' />
    <origin rpy='0 0 0' xyz = '0 0 0' />
  </joint>

  <link name="link1">
    <inertial>
      <origin
        xyz="0.01254 0 0.272"
        rpy="0 0 0" />
      <mass
        value="7.919" />
      <inertia
        ixx="0.044879950"
        ixy="-7.346E-06"
        ixz="-0.006377064"
        iyy="0.047389946"
        iyz="-1.534E-06"
        izz="0.015930027" />
    </inertial>
    <visual>
      <origin xyz="0 0 0" rpy="0 0 0" />
      <geometry>
        <mesh filename="package://addverb_cobot_description/meshes/link1.STL" />
      </geometry>
      <material name="">
        <color rgba="0.75294 0.75294 0.75294 1" />
      </material>
    </visual>
    <collision>
      <origin xyz="0 0 0" rpy="0 0 0" />
      <geometry>
        <mesh filename="package://addverb_cobot_description/meshes/link1.STL" />
      </geometry>
    </collision>
  </link>
  <joint name="joint1" type="revolute">
    <origin xyz="0 0 0" rpy="0 0 0" />
    <parent link="base_link" />
    <child link="link1" />
    <axis xyz="0 0 1" />
    <limit lower="-${pi}" upper="${pi}" effort="150" velocity="3" />
  </joint>
  <link name="link2">
    <inertial>
      <origin
        xyz="0.10537 0 0.14998"
        rpy="0 0 0" />
      <mass
        value="1.017" />
      <inertia
        ixx="0.016383576"
        ixy="0"
        ixz="5.01E-07"
        iyy="0.015505423"
        iyz="8.3217E-06"
        izz="0.001453264" />
    </inertial>
    <visual>
      <origin xyz="0 0 0" rpy="0 0 0" />
      <geometry>
        <mesh filename="package://addverb_cobot_description/meshes/link2.STL" />
      </geometry>
      <material name="">
        <color rgba="0.75294 0.75294 0.75294 1" />
      </material>
    </visual>
    <collision>
      <origin xyz="0 0 0" rpy="0 0 0" />
      <geometry>
        <mesh filename="package://addverb_cobot_description/meshes/link2.STL" />
      </geometry>
    </collision>
  </link>
  <joint name="joint2" type="revolute">
    <origin xyz="0 0 0.346" rpy="0 0 0" />
    <parent link="link1" />
    <child link="link2" />
    <axis xyz="1 0 0" />
    <limit lower="-2.05" upper="0.75" effort="150" velocity="1" />
  </joint>
  <link name="link3">
    <inertial>
      <origin
        xyz="0.01755 0.03359 0"
        rpy="0 0 0" />
      <mass
        value="5.574" />
      <inertia
        ixx="0.021340532"
        ixy="0.003304844"
        ixz="-1.2974E-06"
        iyy="0.009841027"
        iyz="1.3202E-05"
        izz="0.023306443" />
    </inertial>
    <visual>
      <origin xyz="0 0 0" rpy="0 0 0" />
      <geometry>
        <mesh filename="package://addverb_cobot_description/meshes/link3.STL" />
      </geometry>
      <material name="">
        <color rgba="0.75294 0.75294 0.75294 1" />
      </material>
    </visual>
    <collision>
      <origin xyz="0 0 0" rpy="0 0 0" />
      <geometry>
        <mesh filename="package://addverb_cobot_description/meshes/link3.STL" />
      </geometry>
    </collision>
  </link>
  <joint name="joint3" type="revolute">
    <origin xyz="0 0 0.305" rpy="0 0 0" />
    <parent link="link2" />
    <child link="link3" />
    <axis xyz="-1 0 0" />
    <limit lower="-1" upper="1" effort="150" velocity="5" />
  </joint>
  <link name="link4">
    <inertial>
      <origin
        xyz="0.05065 -0.1059 0"
        rpy="0 0 0" />
      <mass
        value="1.894" />
      <inertia
        ixx="0.003626317"
        ixy="-0.000600942"
        ixz="2.750E-06"
        iyy="0.002331370"
        iyz="3.309E-06"
        izz="0.004130374" />
    </inertial>
    <visual>
      <origin xyz="0 0 0" rpy="0 0 0" />
      <geometry>
        <mesh filename="package://addverb_cobot_description/meshes/link4.STL" />
      </geometry>
      <material name="">
        <color rgba="0.75294 0.75294 0.75294 1" />
      </material>
    </visual>
    <collision>
      <origin xyz="0 0 0" rpy="0 0 0" />
      <geometry>
        <mesh filename="package://addverb_cobot_description/meshes/link4.STL" />
      </geometry>
    </collision>
  </link>
  <joint name="joint4" type="revolute">
    <origin xyz="-0.0009127 0.36813 0" rpy="0 0 0" />
    <parent link="link3" />
    <child link="link4" />
    <axis xyz="0 1 0" />
    <limit lower="-${pi}" upper="${pi}" effort="80" velocity="1" />
  </joint>
  <link name="link5">
    <inertial>
      <origin
        xyz="0.00216 -0.00360 -0.04603"
        rpy="0 0 0" />
      <mass
        value="1.791" />
      <inertia
        ixx="0.002516338"
        ixy="6.5634E-05"
        ixz="-0.000102333"
        iyy="0.002442610"
        iyz="0.000185747"
        izz="0.001857540" />
    </inertial>
    <visual>
      <origin xyz="0 0 0" rpy="0 0 0" />
      <geometry>
        <mesh filename="package://addverb_cobot_description/meshes/link5.STL" />
      </geometry>
      <material name="">
        <color rgba="0.75294 0.75294 0.75294 1" />
      </material>
    </visual>
    <collision>
      <origin xyz="0 0 0" rpy="0 0 0" />
      <geometry>
        <mesh filename="package://addverb_cobot_description/meshes/link5.STL" />
      </geometry>
    </collision>
  </link>
  <joint name="joint5" type="revolute">
    <origin xyz="0 0 0" rpy="0 0 0" />
    <parent link="link4" />
    <child link="link5" />
    <axis xyz="-0.5 0.86603 0" />
    <limit lower="-${pi}" upper="${pi}" effort="80" velocity="1" />
  </joint>
  <link name="end-effector" />

  <joint name="joint6" type="revolute">
    <origin xyz="0 0 -0.0975" rpy="0 0 0" />
    <parent link="link5" />
    <child link="end-effector" />
    <axis xyz="0 0 -1" />
    <limit lower="-${pi}" upper="${pi}" effort="80" velocity="1" />
  </joint>
  <link
    name="robotiq_85_base_link">
    <inertial>
      <origin
        xyz="0.00021987 -2.3546E-10 0.030163"
        rpy="0 0 0" />
      <mass
        value="0.30915" />
      <inertia
        ixx="0.00028972"
        ixy="-5.7879E-10"
        ixz="-1.8543E-06"
        iyy="0.00030737"
        iyz="1.682E-12"
        izz="0.00019914" />
    </inertial>
    <visual>
      <origin
        xyz="0 0 0"
        rpy="0 0 0" />
      <geometry>
        <mesh
          filename="package://addverb_cobot_description/meshes/robotiq_85_base_link_fine.STL" />
      </geometry>
      <material
        name="">
        <color
          rgba="0.1 0.1 0.1 1" />
      </material>
    </visual>
    <collision>
      <origin
        xyz="0 0 0"
        rpy="0 0 0" />
      <geometry>
        <mesh
          filename="package://addverb_cobot_description/meshes/robotiq_85_base_link_coarse.STL" />
      </geometry>
    </collision>
  </link>
  <joint name="joint7" type="fixed">
    <origin rpy="0 -3.1416 0" xyz="0 0 0"/>
    <parent link="end-effector"/>
    <child link="robotiq_85_base_link"/>
  </joint>
  
  <link
    name="left_outer_knuckle">
    <inertial>
      <origin
        xyz="0.0178331863169983 3.68915177224286E-11 0.0021442477325704"
        rpy="0 0 0" />
      <mass
        value="0.00684838849434396" />
      <inertia
        ixx="2.66832029033166E-07"
        ixy="1.66142314639824E-15"
        ixz="1.45945633322873E-07"
        iyy="1.3889233257419E-06"
        iyz="2.82951161241588E-15"
        izz="1.26603336914415E-06" />
    </inertial>
    <visual>
      <origin
        xyz="0 0 0"
        rpy="0 0 0" />
      <geometry>
        <mesh
          filename="package://addverb_cobot_description/meshes/outer_knuckle_fine.STL" />
      </geometry>
      <material
        name="">
        <color
          rgba="0.1 0.1 0.1 1" />
      </material>
    </visual>
    <collision>
      <origin
        xyz="0 0 0"
        rpy="0 0 0" />
      <geometry>
        <mesh
          filename="package://addverb_cobot_description/meshes/outer_knuckle_coarse.STL" />
      </geometry>
    </collision>
  </link>
  <joint
    name="finger_joint"
    type="revolute">
    <origin
      xyz="0.0306011444260539 0 0.0627920162695395"
      rpy="0 0 0" />
    <parent
      link="robotiq_85_base_link" />
    <child
      link="left_outer_knuckle" />
    <axis
      xyz="0 -1 0" />
    <limit
	  lower="0"
      upper="0.8757"
      velocity="2.0"
      effort="1000" />
  </joint>
  <link
    name="left_outer_finger">
    <inertial>
      <origin
        xyz="0.00131451599174296 2.88942057994543E-15 0.0215404163180413"
        rpy="0 0 0" />
      <mass
        value="0.0273093985570947" />
      <inertia
        ixx="8.51629628283022E-06"
        ixy="2.58174336207405E-19"
        ixz="3.83829504344079E-07"
        iyy="6.9133328065108E-06"
        iyz="-7.58589926143789E-19"
        izz="2.25006832221981E-06" />
    </inertial>
    <visual>
      <origin
        xyz="0 0 0"
        rpy="0 0 0" />
      <geometry>
        <mesh
          filename="package://addverb_cobot_description/meshes/outer_finger_fine.STL" />
      </geometry>
      <material
        name="">
        <color
          rgba="0.1 0.1 0.1 1" />
      </material>
    </visual>
    <collision>
      <origin
        xyz="0 0 0"
        rpy="0 0 0" />
      <geometry>
        <mesh
          filename="package://addverb_cobot_description/meshes/outer_finger_coarse.STL" />
      </geometry>
    </collision>
  </link>
  <joint
    name="left_outer_finger_joint"
    type="fixed">
    <origin
      xyz="0.0316910442266543 0 -0.00193396375724605"
      rpy="0 0 0" />
    <parent
      link="left_outer_knuckle" />
    <child
      link="left_outer_finger" />
    <axis
      xyz="0 -1 0" />
  </joint>
  <link
    name="left_inner_knuckle">
    <inertial>
      <origin
        xyz="0.017097546626628 -3.93808524389535E-10 0.0224918438201868"
        rpy="0 0 0" />
      <mass
        value="0.0110930853895903" />
      <inertia
        ixx="4.23392770691541E-06"
        ixy="5.748978936968E-15"
        ixz="1.78855677119788E-06"
        iyy="3.96548790524392E-06"
        iyz="1.05464666369669E-14"
        izz="3.24068002883007E-06" />
    </inertial>
    <visual>
      <origin
        xyz="0 0 0"
        rpy="0 0 0" />
      <geometry>
        <mesh
          filename="package://addverb_cobot_description/meshes/inner_knuckle_fine.STL" />
      </geometry>
      <material
        name="">
        <color
          rgba="0.1 0.1 0.1 1" />
      </material>
    </visual>
    <collision>
      <origin
        xyz="0 0 0"
        rpy="0 0 0" />
      <geometry>
        <mesh
          filename="package://addverb_cobot_description/meshes/inner_knuckle_coarse.STL" />
      </geometry>
    </collision>
  </link>
  <joint
    name="left_inner_knuckle_joint"
    type="revolute">
    <origin
      xyz="0.0127000000001501 0 0.0693074999999639"
      rpy="0 0 0" />
    <parent
      link="robotiq_85_base_link" />
    <child
      link="left_inner_knuckle" />
    <axis
      xyz="0 -1 0" />
    <limit
      lower="0"
      upper="0.8757"
      velocity="2.0"
      effort="1000" />
    <mimic 
      joint="finger_joint"
      multiplier="1"
      offset="0" />
  </joint>
  <link
    name="left_inner_finger">
    <inertial>
      <origin
        xyz="0.0060275613594574 -6.29183141465421E-15 0.00669925693133241"
        rpy="0 0 0" />
      <mass
        value="0.00724255346165745" />
      <inertia
        ixx="1.47824274053603E-06"
        ixy="-3.94884463570303E-19"
        ixz="-3.45268847648622E-07"
        iyy="1.70064480838395E-06"
        iyz="3.5059838910097E-19"
        izz="4.77151336838364E-07" />
    </inertial>
    <visual>
      <origin
        xyz="0 0 0"
        rpy="0 0 0" />
      <geometry>
        <mesh
          filename="package://addverb_cobot_description/meshes/inner_finger_fine.STL" />
      </geometry>
      <material
        name="">
        <color
          rgba="0.1 0.1 0.1 1" />
      </material>
    </visual>
    <collision>
      <origin
        xyz="0 0 0"
        rpy="0 0 0" />
      <geometry>
        <mesh
          filename="package://addverb_cobot_description/meshes/inner_finger_coarse.STL" />
      </geometry>
    </collision>
  </link>
  <joint
    name="left_inner_finger_joint"
    type="revolute">
    <origin
      xyz="0.034585310861294 0 0.0454970193817975"
      rpy="0 0 0" />
    <parent
      link="left_inner_knuckle" />
    <child
      link="left_inner_finger" />
    <axis
      xyz="0 -1 0" />
    <limit
      lower="-0.8757"
      upper="0"
      velocity="2.0"
      effort="1000" />
    <mimic 
      joint="finger_joint"
      multiplier="-1"
      offset="0" />
  </joint>
  <link
    name="right_inner_knuckle">
    <inertial>
      <origin
        xyz="0.0168606186773776 3.93808471820465E-10 0.0226699950793434"
        rpy="0 0 0" />
      <mass
        value="0.0110930853895903" />
      <inertia
        ixx="4.27134775939882E-06"
        ixy="-8.53568456728898E-15"
        ixz="1.77774229944246E-06"
        iyy="3.96548790524392E-06"
        iyz="-8.45108024914164E-15"
        izz="3.20325997634666E-06" />
    </inertial>
    <visual>
      <origin
        xyz="0 0 0"
        rpy="0 0 0" />
      <geometry>
        <mesh
          filename="package://addverb_cobot_description/meshes/inner_knuckle_fine.STL" />
      </geometry>
      <material
        name="">
        <color
          rgba="0.1 0.1 0.1 1" />
      </material>
    </visual>
    <collision>
      <origin
        xyz="0 0 0"
        rpy="0 0 0" />
      <geometry>
        <mesh
          filename="package://addverb_cobot_description/meshes/inner_knuckle_coarse.STL" />
      </geometry>
    </collision>
  </link>
  <joint
    name="right_inner_knuckle_joint"
    type="revolute">
    <origin
      xyz="-0.0126999999998499 0 0.0693075000000361"
      rpy="0 0 3.14159265358979" />
    <parent
      link="robotiq_85_base_link" />
    <child
      link="right_inner_knuckle" />
    <axis
      xyz="0 1 0" />
    <limit
      lower="-0.8757"
      upper="0"
      velocity="2.0"
      effort="1000" />
    <mimic 
      joint="finger_joint"
      multiplier="-1"
      offset="0" />
  </joint>
  <link
    name="right_inner_finger">
    <inertial>
      <origin
        xyz="0.00602756228812038 -6.47284509480176E-15 0.00669925609578108"
        rpy="0 0 0" />
      <mass
        value="0.00724255346165744" />
      <inertia
        ixx="1.47824283625957E-06"
        ixy="-3.95952064019123E-19"
        ixz="-3.45268708875543E-07"
        iyy="1.70064480838394E-06"
        iyz="3.55286507960029E-19"
        izz="4.77151241114822E-07" />
    </inertial>
    <visual>
      <origin
        xyz="0 0 0"
        rpy="0 0 0" />
      <geometry>
        <mesh
          filename="package://addverb_cobot_description/meshes/inner_finger_fine.STL" />
      </geometry>
      <material
        name="">
        <color
          rgba="0.1 0.1 0.1 1" />
      </material>
    </visual>
    <collision>
      <origin
        xyz="0 0 0"
        rpy="0 0 0" />
      <geometry>
        <mesh
          filename="package://addverb_cobot_description/meshes/inner_finger_coarse.STL" />
      </geometry>
    </collision>
  </link>
  <joint
    name="right_inner_finger_joint"
    type="revolute">
    <origin
      xyz="0.0341060475457406 0 0.0458573878541688"
      rpy="0 0 0" />
    <parent
      link="right_inner_knuckle" />
    <child
      link="right_inner_finger" />
    <axis
      xyz="0 1 0" />
    <limit
      lower="0"
      upper="0.8757"
      velocity="2.0"
      effort="1000" />
    <mimic 
      joint="finger_joint"
      multiplier="1"
      offset="0" />
  </joint>
  <link
    name="right_outer_knuckle">
    <inertial>
      <origin
        xyz="0.0178097074051638 3.60493211424024E-11 0.00233123458346721"
        rpy="0 0 0" />
      <mass
        value="0.00684838849401352" />
      <inertia
        ixx="2.70004361573169E-07"
        ixy="1.59579467624491E-15"
        ixz="1.56396493788199E-07"
        iyy="1.38892332558312E-06"
        iyz="2.82357800318817E-15"
        izz="1.26286103637978E-06" />
    </inertial>
    <visual>
      <origin
        xyz="0 0 0"
        rpy="0 0 0" />
      <geometry>
        <mesh
          filename="package://addverb_cobot_description/meshes/outer_knuckle_fine.STL" />
      </geometry>
      <material
        name="">
        <color
          rgba="0.1 0.1 0.1 1" />
      </material>
    </visual>
    <collision>
      <origin
        xyz="0 0 0"
        rpy="0 0 0" />
      <geometry>
        <mesh
          filename="package://addverb_cobot_description/meshes/outer_knuckle_coarse.STL" />
      </geometry>
    </collision>
  </link>
  <joint
    name="right_outer_knuckle_joint"
    type="revolute">
    <origin
      xyz="-0.0306011444258893 0 0.0627920162695395"
      rpy="0 0 3.14159265358979" />
    <parent
      link="robotiq_85_base_link" />
    <child
      link="right_outer_knuckle" />
    <axis
      xyz="0 1 0" />
    <limit
      lower="-0.8757"
      upper="0"      
      velocity="2.0"
      effort="1000" /><!-- 0, 0.8757-->
    <mimic 
      joint="finger_joint"
      multiplier="-1"
      offset="0" />
  </joint>
  <link
    name="right_outer_finger">
    <inertial>
      <origin
        xyz="0.00108844269639009 -2.611488350845E-15 0.0215530225245502"
        rpy="0 0 0" />
      <mass
        value="0.0273093985570947" />
      <inertia
        ixx="8.52366028592721E-06"
        ixy="3.41683380899422E-19"
        ixz="3.18003675694284E-07"
        iyy="6.91333280651081E-06"
        iyz="7.37726682706417E-19"
        izz="2.24270431912283E-06" />
    </inertial>
    <visual>
      <origin
        xyz="0 0 0"
        rpy="0 0 0" />
      <geometry>
        <mesh
          filename="package://addverb_cobot_description/meshes/outer_finger_fine.STL" />
      </geometry>
      <material
        name="">
        <color
          rgba="0.1 0.1 0.1 1" />
      </material>
    </visual>
    <collision>
      <origin
        xyz="0 0 0"
        rpy="0 0 0" />
      <geometry>
        <mesh
          filename="package://addverb_cobot_description/meshes/outer_finger_coarse.STL" />
      </geometry>
    </collision>
  </link>
  <joint
    name="right_outer_finger_joint"
    type="fixed">
    <origin
      xyz="0.0317095909367246 0 -0.0016013564954687"
      rpy="0 0 0" />
    <parent
      link="right_outer_knuckle" />
    <child
      link="right_outer_finger" />
    <axis
      xyz="0 1 0" />
  </joint>


  <!-- Dummy joints to satisfy MoveIt when Gazebo publishes _mimic joints -->
  <link name="mimic_dummy_link_1"/>
  <joint name="left_inner_knuckle_joint_mimic" type="fixed">
    <parent link="world" />
    <child link="mimic_dummy_link_1" />
  </joint>

  <link name="mimic_dummy_link_2"/>
  <joint name="left_inner_finger_joint_mimic" type="fixed">
    <parent link="world" />
    <child link="mimic_dummy_link_2" />
  </joint>

  <link name="mimic_dummy_link_3"/>
  <joint name="right_inner_knuckle_joint_mimic" type="fixed">
    <parent link="world" />
    <child link="mimic_dummy_link_3" />
  </joint>

  <link name="mimic_dummy_link_4"/>
  <joint name="right_inner_finger_joint_mimic" type="fixed">
    <parent link="world" />
    <child link="mimic_dummy_link_4" />
  </joint>

  <link name="mimic_dummy_link_5"/>
  <joint name="right_outer_knuckle_joint_mimic" type="fixed">
    <parent link="world" />
    <child link="mimic_dummy_link_5" />
  </joint>

  <link name = "camera_link">

    <inertial>
      <mass value="1.0"/>
      <origin xyz="0 0 0" rpy="0 0 0"/>
      <inertia ixx="1.0" ixy="0.0" ixz="0.0" 
           iyy="1.0" iyz="0.0" 
           izz="1.0"/>
    </inertial>

    <visual>
      <geometry><box size="0.005 0.015 0.015"/></geometry>
    </visual>
    <collision>
      <geometry><box size="0.005 0.015 0.015"/></geometry>
    </collision>
  </link>

  <joint name = "camera_joint" type="fixed">
    <parent link = "robotiq_85_base_link"/>
    <child link = "camera_link"/>
    <origin xyz = "0 0.025 0.08" rpy = "3.14 -1.57 3.14"/>
  </joint>

  <link name = "camera_optical"></link>

  <joint name = "camera_optical_joint" type = "fixed">
    <origin xyz = "0 0 0" rpy = "-1.57 0 -1.57" />
    <parent link = "camera_link" />
    <child link  = "camera_optical" />
  </joint>


  <!-- <gazebo reference = "camera_link">
    <sensor name = 'camera' type = 'camera'>
      <pose> 0 0 0 0 0 0</pose>
      <visualize>true</visualize>
      <update_rate>5</update_rate>
      <gz_frame_id>/camera_link</gz_frame_id>
      <camera>
        <horizontal_fov>1</horizontal_fov>
        <image>
          <format>R8G8B8</format>
          <width>640</width>
          <height>480</height>
        </image>
        <clip>
          <near>0.02</near>
          <far>20</far>
        </clip>
      </camera>
       <plugin name = "camera_controller" filename = "libgazebo_ros_camera.so">
        <frame_name>camera_optical</frame_name>
        <image_topic_name>image_raw</image_topic_name>
        <always_on>true</always_on>
      </plugin>
    </sensor>
  </gazebo> -->

  <gazebo reference="camera_link">
    <sensor name="camera" type="camera">
        <always_on>true</always_on>
        <update_rate>30.0</update_rate>
        <visualize>true</visualize>
        <topic>/image_raw</topic>
        <gz_frame_id>/camera_link</gz_frame_id>
        <camera name="camera">
          <horizontal_fov>1.21126</horizontal_fov>
          <image>
            <width>2304</width>
            <height>1296</height>
            <format>R8G8B8</format>
          </image>
          <distortion>
            <k1>0.0</k1>
            <k2>0.0</k2>
            <k3>0.0</k3>
            <p1>0.0</p1>
            <p2>0.0</p2>
            <center>0.5 0.5</center>
          </distortion>
        </camera>
    </sensor>   
</gazebo>

<gazebo reference="left_inner_finger">
    <mu1>1000.0</mu1>
    <mu2>1000.0</mu2>
    <kp>1000000.0</kp>
    <kd>1.0</kd>
    <minDepth>0.001</minDepth>
    <maxVel>0.1</maxVel>
</gazebo>

<gazebo reference="right_inner_finger">
    <mu1>1000.0</mu1>
    <mu2>1000.0</mu2>
    <kp>1000000.0</kp>
    <kd>1.0</kd>
    <minDepth>0.001</minDepth>
    <maxVel>0.1</maxVel>
</gazebo>

<gazebo>
    <plugin filename="ignition-gazebo-detachable-joint-system" name="ignition::gazebo::systems::DetachableJoint">
          <parent_link>left_inner_finger</parent_link>
          <child_model>blue_cube</child_model>
          <child_link>link</child_link>
          <attach_topic>/gripper/attach</attach_topic>
          <detach_topic>/gripper/detach</detach_topic>
          <output_topic>/gripper/status</output_topic>
          <initial_attach>false</initial_attach>
    </plugin>

    <plugin filename="ignition-gazebo-detachable-joint-system" name="ignition::gazebo::systems::DetachableJoint">
          <parent_link>left_inner_finger</parent_link>
          <child_model>red_cube</child_model>
          <child_link>link</child_link>
          <attach_topic>/gripper/attach_red</attach_topic>
          <detach_topic>/gripper/detach_red</detach_topic>
          <output_topic>/gripper/status_red</output_topic>
          <initial_attach>false</initial_attach>
    </plugin>

    <plugin filename="ignition-gazebo-detachable-joint-system" name="ignition::gazebo::systems::DetachableJoint">
          <parent_link>left_inner_finger</parent_link>
          <child_model>yellow_cube</child_model>
          <child_link>link</child_link>
          <attach_topic>/gripper/attach_yellow</attach_topic>
          <detach_topic>/gripper/detach_yellow</detach_topic>
          <output_topic>/gripper/status_yellow</output_topic>
          <initial_attach>false</initial_attach>
    </plugin>

    <plugin filename="ignition-gazebo-detachable-joint-system" name="ignition::gazebo::systems::DetachableJoint">
          <parent_link>left_inner_finger</parent_link>
          <child_model>green_cube</child_model>
          <child_link>link</child_link>
          <attach_topic>/gripper/attach_green</attach_topic>
          <detach_topic>/gripper/detach_green</detach_topic>
          <output_topic>/gripper/status_green</output_topic>
          <initial_attach>false</initial_attach>
    </plugin>
    
</gazebo>


</robot>